Workbook

Sheet 안내
A1: Tour Navigator 장소 재분류 초안
A3: 목적: 장소마다 카테고리를 하나만 붙이던 방식을 "주 카테고리 + 보조 카테고리 + 성격 태그"로 바꾼 초안입니다.
A4: 범위: 장소 마스터(assets/tour-places.csv) 1,197곳 + 마스터에 없고 테마 화면에만 있는 72곳 = 총 1,269곳.
A5: 분류 방식: 기존 분류를 주 카테고리로 두고, 장소명·설명의 키워드 규칙으로 보조 카테고리와 태그를 제안했습니다. 바닷가 장소(해수욕장·해변·해안·포구 등)는 주 카테고리를 해양·자연으로 옮겼습니다.
A6: 테마 계산: 보조가 있으면 주 0.6 + 보조 0.4, 없으면 주 1.0으로 셉니다. 숙박은 계산에서 뺍니다.
A7: 수정 방법: 「장소 분류」 시트의 노란 칸(주 카테고리, 보조 카테고리, 성격 태그, 걷기 난이도)만 고치면 「테마 프로필」「군집 적합」 시트가 자동으로 다시 계산됩니다.
A8: 검토 우선순위: "변경=Y"(주 카테고리가 바뀐 곳)와 "검토 필요=Y"(분류가 비어 있었거나 설명에서만 바다가 나온 곳)부터 확인해 주세요.
A9: 성격 태그: 바다 / 야경 / 실내 / 촬영명소. 걷기 난이도: 상(산·오름·둘레길) / 중(공원·해안·마을) / 하.
A10: 주의: 규칙 기반 자동 분류라 오분류가 있을 수 있습니다(예: 태종대온천, 삼익비치타운 벚꽃길은 판단이 필요).
A12: 요약 (자동 계산)
A13: 전체 장소 수 | B13: =COUNTA('장소 분류'!D2:D2000) -> 1269
A14: 주 카테고리 변경 (변경=Y) | B14: =COUNTIF('장소 분류'!L2:L2000,"Y") -> 40
A15: 검토 필요 (검토=Y) | B15: =COUNTIF('장소 분류'!M2:M2000,"Y") -> 88
A16: 보조 카테고리 있음 | B16: =COUNTIF('장소 분류'!I2:I2000,"?*") -> 425
A17: 주 카테고리 = 역사·문화 | B17: =COUNTIF('장소 분류'!H2:H2000,"역사·문화") -> 315
A18: 주 카테고리 = 힐링·생태 | B18: =COUNTIF('장소 분류'!H2:H2000,"힐링·생태") -> 324
A19: 주 카테고리 = 테마파크·액티비티 | B19: =COUNTIF('장소 분류'!H2:H2000,"테마파크·액티비티") -> 210
A20: 주 카테고리 = 로컬·먹거리 | B20: =COUNTIF('장소 분류'!H2:H2000,"로컬·먹거리") -> 119
A21: 주 카테고리 = 해양·자연 | B21: =COUNTIF('장소 분류'!H2:H2000,"해양·자연") -> 147
A22: 주 카테고리 = 숙박 | B22: =COUNTIF('장소 분류'!H2:H2000,"숙박") -> 154
A23: 태그: 야경 | B23: =COUNTIF('장소 분류'!J2:J2000,"*야경*") -> 55
A24: 태그: 바다 | B24: =COUNTIF('장소 분류'!J2:J2000,"*바다*") -> 255
A25: 태그: 실내 | B25: =COUNTIF('장소 분류'!J2:J2000,"*실내*") -> 128

Sheet 장소 분류
A1: No | B1: 출처 | C1: 도시 | D1: 장소명 | E1: 영문 | F1: 포함 테마 | G1: 현재 분류(앱) | H1: 주 카테고리(제안) | I1: 보조 카테고리(제안) | J1: 성격 태그 | K1: 걷기 난이도 | L1: 변경 | M1: 검토 필요 | N1: 판단 근거 | O1: 설명 | P1: w:역사·문화 | Q1: w:힐링·생태 | R1: w:테마파크·액티비티 | S1: w:로컬·먹거리 | T1: w:해양·자연 | U1: 야경 | V1: 계산 대상
A2: 1 | B2: 장소 마스터 | D2: 곽지과물해변 | E2: Gwakji Beach | F2: 제주 K-Drama | G2: 힐링·생태 | H2: 해양·자연 | I2: 힐링·생태 | J2: 바다, 촬영명소 | K2: 중 | L2: Y | N2: 바닷가 장소 → 주 카테고리 해양으로 변경 | O2: 모래밭에 용천수가 솟는 해변. 애월 산책로와 이어진다. | P2: =IF($H2="숙박",0,IF($H2=MID(P$1,3,20),IF($I2="",1,0.6),IF($I2=MID(P$1,3,20),0.4,0))) -> 0 | Q2: =IF($H2="숙박",0,IF($H2=MID(Q$1,3,20),IF($I2="",1,0.6),IF($I2=MID(Q$1,3,20),0.4,0))) -> 0.4 | R2: =IF($H2="숙박",0,IF($H2=MID(R$1,3,20),IF($I2="",1,0.6),IF($I2=MID(R$1,3,20),0.4,0))) -> 0 | S2: =IF($H2="숙박",0,IF($H2=MID(S$1,3,20),IF($I2="",1,0.6),IF($I2=MID(S$1,3,20),0.4,0))) -> 0 | T2: =IF($H2="숙박",0,IF($H2=MID(T$1,3,20),IF($I2="",1,0.6),IF($I2=MID(T$1,3,20),0.4,0))) -> 0.6 | U2: =IF($H2="숙박",0,IF(ISNUMBER(SEARCH("야경",$J2)),1,0)) -> 0 | V2: =IF($H2="숙박",0,1) -> 1
A3: 2 | B3: 테마 파일 (부산 영화 기행) | D3: 광안리해변 · 광안대교 | E3: Gwangalli Beach & Diamond Bridge | F3: 부산 영화 기행 | G3: 힐링·생태 | H3: 해양·자연 | I3: 힐링·생태 | J3: 바다, 야경, 촬영명소 | K3: 중 | L3: Y | N3: 바닷가 장소 → 주 카테고리 해양으로 변경 | O3: 7.4km 현수교와 이를 정면으로 마주 보는 해변. 야간 조명과 드론쇼가 열리며, 재난·액션물의 클라이맥스 배경으로 반복해서 등장한다. | P3: =IF($H3="숙박",0,IF($H3=MID(P$1,3,20),IF($I3="",1,0.6),IF($I3=MID(P$1,3,20),0.4,0))) -> 0 | Q3: =IF($H3="숙박",0,IF($H3=MID(Q$1,3,20),IF($I3="",1,0.6),IF($I3=MID(Q$1,3,20),0.4,0))) -> 0.4 | R3: =IF($H3="숙박",0,IF($H3=MID(R$1,3,20),IF($I3="",1,0.6),IF($I3=MID(R$1,3,20),0.4,0))) -> 0 | S3: =IF($H3="숙박",0,IF($H3=MID(S$1,3,20),IF($I3="",1,0.6),IF($I3=MID(S$1,3,20),0.4,0))) -> 0 | T3: =IF($H3="숙박",0,IF($H3=MID(T$1,3,20),IF($I3="",1,0.6),IF($I3=MID(T$1,3,20),0.4,0))) -> 0.6 | U3: =IF($H3="숙박",0,IF(ISNUMBER(SEARCH("야경",$J3)),1,0)) -> 1 | V3: =IF($H3="숙박",0,1) -> 1
A4: 3 | B4: 테마 파일 (제주 K-Drama) | D4: 광치기해변 | E4: Gwangchigi Beach | F4: 제주 K-Drama | G4: 힐링·생태 | H4: 해양·자연 | I4: 힐링·생태 | J4: 바다, 촬영명소 | K4: 중 | L4: Y | N4: 바닷가 장소 → 주 카테고리 해양으로 변경 | O4: 썰물에 이끼 낀 암반이 초록으로 드러나는 해변. 성산일출봉을 정면으로 마주 본다. | P4: =IF($H4="숙박",0,IF($H4=MID(P$1,3,20),IF($I4="",1,0.6),IF($I4=MID(P$1,3,20),0.4,0))) -> 0 | Q4: =IF($H4="숙박",0,IF($H4=MID(Q$1,3,20),IF($I4="",1,0.6),IF($I4=MID(Q$1,3,20),0.4,0))) -> 0.4 | R4: =IF($H4="숙박",0,IF($H4=MID(R$1,3,20),IF($I4="",1,0.6),IF($I4=MID(R$1,3,20),0.4,0))) -> 0 | S4: =IF($H4="숙박",0,IF($H4=MID(S$1,3,20),IF($I4="",1,0.6),IF($I4=MID(S$1,3,20),0.4,0))) -> 0 | T4: =IF($H4="숙박",0,IF($H4=MID(T$1,3,20),IF($I4="",1,0.6),IF($I4=MID(T$1,3,20),0.4,0))) -> 0.6 | U4: =IF($H4="숙박",0,IF(ISNUMBER(SEARCH("야경",$J4)),1,0)) -> 0 | V4: =IF($H4="숙박",0,1) -> 1
A5: 4 | B5: 테마 파일 (제주 K-Drama) | D5: 금능포구 돌담길 | E5: Geumneung Harbour Stone Walls | F5: 제주 K-Drama | G5: 힐링·생태 | H5: 해양·자연 | I5: 힐링·생태 | J5: 바다, 촬영명소 | K5: 중 | L5: Y | N5: 바닷가 장소 → 주 카테고리 해양으로 변경 | O5: 검은 현무암 돌담이 바다까지 이어지는 포구. 옴니버스 인물들이 오가던 마을 길의 배경으로 소개된 구간이다. | P5: =IF($H5="숙박",0,IF($H5=MID(P$1,3,20),IF($I5="",1,0.6),IF($I5=MID(P$1,3,20),0.4,0))) -> 0 | Q5: =IF($H5="숙박",0,IF($H5=MID(Q$1,3,20),IF($I5="",1,0.6),IF($I5=MID(Q$1,3,20),0.4,0))) -> 0.4 | R5: =IF($H5="숙박",0,IF($H5=MID(R$1,3,20),IF($I5="",1,0.6),IF($I5=MID(R$1,3,20),0.4,0))) -> 0 | S5: =IF($H5="숙박",0,IF($H5=MID(S$1,3,20),IF($I5="",1,0.6),IF($I5=MID(S$1,3,20),0.4,0))) -> 0 | T5: =IF($H5="숙박",0,IF($H5=MID(T$1,3,20),IF($I5="",1,0.6),IF($I5=MID(T$1,3,20),0.4,0))) -> 0.6 | U5: =IF($H5="숙박",0,IF(ISNUMBER(SEARCH("야경",$J5)),1,0)) -> 0 | V5: =IF($H5="숙박",0,1) -> 1
A6: 5 | B6: 장소 마스터 | D6: 기장 죽성 해안 | E6: Jukseong Coast | F6: 부산 영화 기행 | G6: 힐링·생태 | H6: 해양·자연 | I6: 힐링·생태 | J6: 바다, 촬영명소 | K6: 중 | L6: Y | N6: 바닷가 장소 → 주 카테고리 해양으로 변경 | O6: 갯바위와 방파제가 이어지는 조용한 해안. | P6: =IF($H6="숙박",0,IF($H6=MID(P$1,3,20),IF($I6="",1,0.6),IF($I6=MID(P$1,3,20),0.4,0))) -> 0 | Q6: =IF($H6="숙박",0,IF($H6=MID(Q$1,3,20),IF($I6="",1,0.6),IF($I6=MID(Q$1,3,20),0.4,0))) -> 0.4 | R6: =IF($H6="숙박",0,IF($H6=MID(R$1,3,20),IF($I6="",1,0.6),IF($I6=MID(R$1,3,20),0.4,0))) -> 0 | S6: =IF($H6="숙박",0,IF($H6=MID(S$1,3,20),IF($I6="",1,0.6),IF($I6=MID(S$1,3,20),0.4,0))) -> 0 | T6: =IF($H6="숙박",0,IF($H6=MID(T$1,3,20),IF($I6="",1,0.6),IF($I6=MID(T$1,3,20),0.4,0))) -> 0.6 | U6: =IF($H6="숙박",0,IF(ISNUMBER(SEARCH("야경",$J6)),1,0)) -> 0 | V6: =IF($H6="숙박",0,1) -> 1
A7: 6 | B7: 장소 마스터 | D7: 김녕성세기해변 | E7: Gimnyeong Seongsegi Beach | F7: 제주 K-Drama | G7: 힐링·생태 | H7: 해양·자연 | I7: 힐링·생태 | J7: 바다, 촬영명소 | K7: 중 | L7: Y | N7: 바닷가 장소 → 주 카테고리 해양으로 변경 | O7: 김녕 본 해변 옆의 작은 만. 물빛이 더 짙다. | P7: =IF($H7="숙박",0,IF($H7=MID(P$1,3,20),IF($I7="",1,0.6),IF($I7=MID(P$1,3,20),0.4,0))) -> 0 | Q7: =IF($H7="숙박",0,IF($H7=MID(Q$1,3,20),IF($I7="",1,0.6),IF($I7=MID(Q$1,3,20),0.4,0))) -> 0.4 | R7: =IF($H7="숙박",0,IF($H7=MID(R$1,3,20),IF($I7="",1,0.6),IF($I7=MID(R$1,3,20),0.4,0))) -> 0 | S7: =IF($H7="숙박",0,IF($H7=MID(S$1,3,20),IF($I7="",1,0.6),IF($I7=MID(S$1,3,20),0.4,0))) -> 0 | T7: =IF($H7="숙박",0,IF($H7=MID(T$1,3,20),IF($I7="",1,0.6),IF($I7=MID(T$1,3,20),0.4,0))) -> 0.6 | U7: =IF($H7="숙박",0,IF(ISNUMBER(SEARCH("야경",$J7)),1,0)) -> 0 | V7: =IF($H7="숙박",0,1) -> 1
A8: 7 | B8: 테마 파일 (제주 K-Drama) | D8: 김녕해수욕장 | E8: Gimnyeong Beach | F8: 제주 K-Drama | G8: 힐링·생태 | H8: 해양·자연 | I8: 힐링·생태 | J8: 바다, 촬영명소 | K8: 중 | L8: Y | N8: 바닷가 장소 → 주 카테고리 해양으로 변경 | O8: 어린 애순이가 엄마를 기다리며 뛰어놀던 해변. 물빛이 옅은 청록으로 얕게 깔리고, 뒤로 풍력발전기가 줄지어 선다. | P8: =IF($H8="숙박",0,IF($H8=MID(P$1,3,20),IF($I8="",1,0.6),IF($I8=MID(P$1,3,20),0.4,0))) -> 0 | Q8: =IF($H8="숙박",0,IF($H8=MID(Q$1,3,20),IF($I8="",1,0.6),IF($I8=MID(Q$1,3,20),0.4,0))) -> 0.4 | R8: =IF($H8="숙박",0,IF($H8=MID(R$1,3,20),IF($I8="",1,0.6),IF($I8=MID(R$1,3,20),0.4,0))) -> 0 | S8: =IF($H8="숙박",0,IF($H8=MID(S$1,3,20),IF($I8="",1,0.6),IF($I8=MID(S$1,3,20),0.4,0))) -> 0 | T8: =IF($H8="숙박",0,IF($H8=MID(T$1,3,20),IF($I8="",1,0.6),IF($I8=MID(T$1,3,20),0.4,0))) -> 0.6 | U8: =IF($H8="숙박",0,IF(ISNUMBER(SEARCH("야경",$J8)),1,0)) -> 0 | V8: =IF($H8="숙박",0,1) -> 1
A9: 8 | B9: 장소 마스터 | D9: 남원 큰엉해안경승지 | E9: Keunnyeong Coastal Walk | F9: 제주 K-Drama | G9: 힐링·생태 | H9: 해양·자연 | I9: 힐링·생태 | J9: 바다, 촬영명소 | K9: 중 | L9: Y | N9: 바닷가 장소 → 주 카테고리 해양으로 변경 | O9: 절벽 위로 난 산책로. 한반도 모양으로 뚫린 나뭇잎 구간이 알려져 있다. | P9: =IF($H9="숙박",0,IF($H9=MID(P$1,3,20),IF($I9="",1,0.6),IF($I9=MID(P$1,3,20),0.4,0))) -> 0 | Q9: =IF($H9="숙박",0,IF($H9=MID(Q$1,3,20),IF($I9="",1,0.6),IF($I9=MID(Q$1,3,20),0.4,0))) -> 0.4 | R9: =IF($H9="숙박",0,IF($H9=MID(R$1,3,20),IF($I9="",1,0.6),IF($I9=MID(R$1,3,20),0.4,0))) -> 0 | S9: =IF($H9="숙박",0,IF($H9=MID(S$1,3,20),IF($I9="",1,0.6),IF($I9=MID(S$1,3,20),0.4,0))) -> 0 | T9: =IF($H9="숙박",0,IF($H9=MID(T$1,3,20),IF($I9="",1,0.6),IF($I9=MID(T$1,3,20),0.4,0))) -> 0.6 | U9: =IF($H9="숙박",0,IF(ISNUMBER(SEARCH("야경",$J9)),1,0)) -> 0 | V9: =IF($H9="숙박",0,1) -> 1
A10: 9 | B10: 장소 마스터 | D10: 동백섬 · 누리마루 | E10: Dongbaekseom & Nurimaru | F10: 부산 영화 기행 | G10: 힐링·생태 | H10: 해양·자연 | I10: 힐링·생태 | J10: 바다, 촬영명소 | K10: 중 | L10: Y | N10: 바닷가 장소 → 주 카테고리 해양으로 변경 | O10: 해운대 서쪽 끝 육계도. 해안 산책로가 누리마루 APEC하우스로 이어진다. | P10: =IF($H10="숙박",0,IF($H10=MID(P$1,3,20),IF($I10="",1,0.6),IF($I10=MID(P$1,3,20),0.4,0))) -> 0 | Q10: =IF($H10="숙박",0,IF($H10=MID(Q$1,3,20),IF($I10="",1,0.6),IF($I10=MID(Q$1,3,20),0.4,0))) -> 0.4 | R10: =IF($H10="숙박",0,IF($H10=MID(R$1,3,20),IF($I10="",1,0.6),IF($I10=MID(R$1,3,20),0.4,0))) -> 0 | S10: =IF($H10="숙박",0,IF($H10=MID(S$1,3,20),IF($I10="",1,0.6),IF($I10=MID(S$1,3,20),0.4,0))) -> 0 | T10: =IF($H10="숙박",0,IF($H10=MID(T$1,3,20),IF($I10="",1,0.6),IF($I10=MID(T$1,3,20),0.4,0))) -> 0.6 | U10: =IF($H10="숙박",0,IF(ISNUMBER(SEARCH("야경",$J10)),1,0)) -> 0 | V10: =IF($H10="숙박",0,1) -> 1
A11: 10 | B11: 장소 마스터 | D11: 부네치아 (장림포구) | E11: Bunezia (Jangnim Port) | F11: 부산 영화 기행 | G11: 힐링·생태 | H11: 해양·자연 | I11: 힐링·생태 | J11: 바다, 촬영명소 | K11: 중 | L11: Y | N11: 바닷가 장소 → 주 카테고리 해양으로 변경 | O11: 색색의 창고가 물가에 늘어선 포구. 베네치아를 빗대 부네치아로 불린다. | P11: =IF($H11="숙박",0,IF($H11=MID(P$1,3,20),IF($I11="",1,0.6),IF($I11=MID(P$1,3,20),0.4,0))) -> 0 | Q11: =IF($H11="숙박",0,IF($H11=MID(Q$1,3,20),IF($I11="",1,0.6),IF($I11=MID(Q$1,3,20),0.4,0))) -> 0.4 | R11: =IF($H11="숙박",0,IF($H11=MID(R$1,3,20),IF($I11="",1,0.6),IF($I11=MID(R$1,3,20),0.4,0))) -> 0 | S11: =IF($H11="숙박",0,IF($H11=MID(S$1,3,20),IF($I11="",1,0.6),IF($I11=MID(S$1,3,20),0.4,0))) -> 0 | T11: =IF($H11="숙박",0,IF($H11=MID(T$1,3,20),IF($I11="",1,0.6),IF($I11=MID(T$1,3,20),0.4,0))) -> 0.6 | U11: =IF($H11="숙박",0,IF(ISNUMBER(SEARCH("야경",$J11)),1,0)) -> 0 | V11: =IF($H11="숙박",0,1) -> 1
A12: 11 | B12: 장소 마스터 | D12: 부산 아난티 · 힐튼 해안 | E12: Ananti Coast | F12: 부산 영화 기행 | G12: 힐링·생태 | H12: 해양·자연 | I12: 힐링·생태 | J12: 바다, 촬영명소 | K12: 중 | L12: Y | N12: 바닷가 장소 → 주 카테고리 해양으로 변경 | O12: 절벽 위 리조트 단지의 공개 산책로와 서점. | P12: =IF($H12="숙박",0,IF($H12=MID(P$1,3,20),IF($I12="",1,0.6),IF($I12=MID(P$1,3,20),0.4,0))) -> 0 | Q12: =IF($H12="숙박",0,IF($H12=MID(Q$1,3,20),IF($I12="",1,0.6),IF($I12=MID(Q$1,3,20),0.4,0))) -> 0.4 | R12: =IF($H12="숙박",0,IF($H12=MID(R$1,3,20),IF($I12="",1,0.6),IF($I12=MID(R$1,3,20),0.4,0))) -> 0 | S12: =IF($H12="숙박",0,IF($H12=MID(S$1,3,20),IF($I12="",1,0.6),IF($I12=MID(S$1,3,20),0.4,0))) -> 0 | T12: =IF($H12="숙박",0,IF($H12=MID(T$1,3,20),IF($I12="",1,0.6),IF($I12=MID(T$1,3,20),0.4,0))) -> 0.6 | U12: =IF($H12="숙박",0,IF(ISNUMBER(SEARCH("야경",$J12)),1,0)) -> 0 | V12: =IF($H12="숙박",0,1) -> 1
A13: 12 | B13: 장소 마스터 | D13: 부산항 북항 친수공원 | E13: North Port Waterfront Park | F13: 부산 영화 기행 | G13: 힐링·생태 | H13: 해양·자연 | I13: 힐링·생태 | J13: 바다, 촬영명소 | K13: 중 | L13: Y | N13: 바닷가 장소 → 주 카테고리 해양으로 변경 | O13: 재개발한 항만 부지의 수변 공원. 크루즈 부두가 보인다. | P13: =IF($H13="숙박",0,IF($H13=MID(P$1,3,20),IF($I13="",1,0.6),IF($I13=MID(P$1,3,20),0.4,0))) -> 0 | Q13: =IF($H13="숙박",0,IF($H13=MID(Q$1,3,20),IF($I13="",1,0.6),IF($I13=MID(Q$1,3,20),0.4,0))) -> 0.4 | R13: =IF($H13="숙박",0,IF($H13=MID(R$1,3,20),IF($I13="",1,0.6),IF($I13=MID(R$1,3,20),0.4,0))) -> 0 | S13: =IF($H13="숙박",0,IF($H13=MID(S$1,3,20),IF($I13="",1,0.6),IF($I13=MID(S$1,3,20),0.4,0))) -> 0 | T13: =IF($H13="숙박",0,IF($H13=MID(T$1,3,20),IF($I13="",1,0.6),IF($I13=MID(T$1,3,20),0.4,0))) -> 0.6 | U13: =IF($H13="숙박",0,IF(ISNUMBER(SEARCH("야경",$J13)),1,0)) -> 0 | V13: =IF($H13="숙박",0,1) -> 1
... A37: 36 | B37: 장소 마스터 | D37: 흰여울 절영해안산책로 | E37: Jeollyeong Coastal Walk | F37: 부산 영화 기행 | G37: 힐링·생태 | H37: 해양·자연 | I37: 힐링·생태 | J37: 바다, 촬영명소 | K37: 중 | L37: Y | N37: 바닷가 장소 → 주 카테고리 해양으로 변경 | O37: 흰여울마을 아래 해안으로 내려가는 길. 파도 소리가 가깝다. | P37: =IF($H37="숙박",0,IF($H37=MID(P$1,3,20),IF($I37="",1,0.6),IF($I37=MID(P$1,3,20),0.4,0))) -> 0 | Q37: =IF($H37="숙박",0,IF($H37=MID(Q$1,3,20),IF($I37="",1,0.6),IF($I37=MID(Q$1,3,20),0.4,0))) -> 0.4 | R37: =IF($H37="숙박",0,IF($H37=MID(R$1,3,20),IF($I37="",1,0.6),IF($I37=MID(R$1,3,20),0.4,0))) -> 0 | S37: =IF($H37="숙박",0,IF($H37=MID(S$1,3,20),IF($I37="",1,0.6),IF($I37=MID(S$1,3,20),0.4,0))) -> 0 | T37: =IF($H37="숙박",0,IF($H37=MID(T$1,3,20),IF($I37="",1,0.6),IF($I37=MID(T$1,3,20),0.4,0))) -> 0.6 | U37: =IF($H37="숙박",0,IF(ISNUMBER(SEARCH("야경",$J37)),1,0)) -> 0 | V37: =IF($H37="숙박",0,1) -> 1
A38: 37 | B38: 장소 마스터 | C38: 거제 | D38: 공곶이 | E38: Gonggoji | G38: 힐링·생태 | H38: 해양·자연 | I38: 힐링·생태 | J38: 바다 | K38: 중 | L38: Y | N38: 바닷가 장소 → 주 카테고리 해양으로 변경 | O38: 수선화가 덮는 바닷가 계단 농원. | P38: =IF($H38="숙박",0,IF($H38=MID(P$1,3,20),IF($I38="",1,0.6),IF($I38=MID(P$1,3,20),0.4,0))) -> 0 | Q38: =IF($H38="숙박",0,IF($H38=MID(Q$1,3,20),IF($I38="",1,0.6),IF($I38=MID(Q$1,3,20),0.4,0))) -> 0.4 | R38: =IF($H38="숙박",0,IF($H38=MID(R$1,3,20),IF($I38="",1,0.6),IF($I38=MID(R$1,3,20),0.4,0))) -> 0 | S38: =IF($H38="숙박",0,IF($H38=MID(S$1,3,20),IF($I38="",1,0.6),IF($I38=MID(S$1,3,20),0.4,0))) -> 0 | T38: =IF($H38="숙박",0,IF($H38=MID(T$1,3,20),IF($I38="",1,0.6),IF($I38=MID(T$1,3,20),0.4,0))) -> 0.6 | U38: =IF($H38="숙박",0,IF(ISNUMBER(SEARCH("야경",$J38)),1,0)) -> 0 | V38: =IF($H38="숙박",0,1) -> 1
A39: 38 | B39: 장소 마스터 | C39: 영덕 | D39: 삼사해상공원 | E39: Samsa Maritime Park | G39: 힐링·생태 | H39: 해양·자연 | I39: 힐링·생태 | J39: 바다 | K39: 중 | L39: Y | N39: 바닷가 장소 → 주 카테고리 해양으로 변경 | O39: 동해를 내려다보는 언덕 공원. 대종이 있다. | P39: =IF($H39="숙박",0,IF($H39=MID(P$1,3,20),IF($I39="",1,0.6),IF($I39=MID(P$1,3,20),0.4,0))) -> 0 | Q39: =IF($H39="숙박",0,IF($H39=MID(Q$1,3,20),IF($I39="",1,0.6),IF($I39=MID(Q$1,3,20),0.4,0))) -> 0.4 | R39: =IF($H39="숙박",0,IF($H39=MID(R$1,3,20),IF($I39="",1,0.6),IF($I39=MID(R$1,3,20),0.4,0))) -> 0 | S39: =IF($H39="숙박",0,IF($H39=MID(S$1,3,20),IF($I39="",1,0.6),IF($I39=MID(S$1,3,20),0.4,0))) -> 0 | T39: =IF($H39="숙박",0,IF($H39=MID(T$1,3,20),IF($I39="",1,0.6),IF($I39=MID(T$1,3,20),0.4,0))) -> 0.6 | U39: =IF($H39="숙박",0,IF(ISNUMBER(SEARCH("야경",$J39)),1,0)) -> 0 | V39: =IF($H39="숙박",0,1) -> 1
A40: 39 | B40: 장소 마스터 | C40: 태안 | D40: 신두리 해안사구 | E40: Sinduri Coastal Dunes | G40: 힐링·생태 | H40: 해양·자연 | I40: 힐링·생태 | J40: 바다 | K40: 중 | L40: Y | N40: 바닷가 장소 → 주 카테고리 해양으로 변경 | O40: 한국 최대의 해안 사구. 천연기념물이다. | P40: =IF($H40="숙박",0,IF($H40=MID(P$1,3,20),IF($I40="",1,0.6),IF($I40=MID(P$1,3,20),0.4,0))) -> 0 | Q40: =IF($H40="숙박",0,IF($H40=MID(Q$1,3,20),IF($I40="",1,0.6),IF($I40=MID(Q$1,3,20),0.4,0))) -> 0.4 | R40: =IF($H40="숙박",0,IF($H40=MID(R$1,3,20),IF($I40="",1,0.6),IF($I40=MID(R$1,3,20),0.4,0))) -> 0 | S40: =IF($H40="숙박",0,IF($H40=MID(S$1,3,20),IF($I40="",1,0.6),IF($I40=MID(S$1,3,20),0.4,0))) -> 0 | T40: =IF($H40="숙박",0,IF($H40=MID(T$1,3,20),IF($I40="",1,0.6),IF($I40=MID(T$1,3,20),0.4,0))) -> 0.6 | U40: =IF($H40="숙박",0,IF(ISNUMBER(SEARCH("야경",$J40)),1,0)) -> 0 | V40: =IF($H40="숙박",0,1) -> 1
A41: 40 | B41: 장소 마스터 | C41: 통영 | D41: 장사도 해상공원 | E41: Jangsado Sea Park | G41: 힐링·생태 | H41: 해양·자연 | I41: 힐링·생태 | J41: 바다 | K41: 중 | L41: Y | N41: 바닷가 장소 → 주 카테고리 해양으로 변경 | O41: 동백과 야생화가 덮인 정원 섬. | P41: =IF($H41="숙박",0,IF($H41=MID(P$1,3,20),IF($I41="",1,0.6),IF($I41=MID(P$1,3,20),0.4,0))) -> 0 | Q41: =IF($H41="숙박",0,IF($H41=MID(Q$1,3,20),IF($I41="",1,0.6),IF($I41=MID(Q$1,3,20),0.4,0))) -> 0.4 | R41: =IF($H41="숙박",0,IF($H41=MID(R$1,3,20),IF($I41="",1,0.6),IF($I41=MID(R$1,3,20),0.4,0))) -> 0 | S41: =IF($H41="숙박",0,IF($H41=MID(S$1,3,20),IF($I41="",1,0.6),IF($I41=MID(S$1,3,20),0.4,0))) -> 0 | T41: =IF($H41="숙박",0,IF($H41=MID(T$1,3,20),IF($I41="",1,0.6),IF($I41=MID(T$1,3,20),0.4,0))) -> 0.6 | U41: =IF($H41="숙박",0,IF(ISNUMBER(SEARCH("야경",$J41)),1,0)) -> 0 | V41: =IF($H41="숙박",0,1) -> 1
A42: 41 | B42: 장소 마스터 | D42: 가파도 | E42: Gapado Island | F42: 제주 K-Drama | G42: 테마파크·액티비티 | H42: 테마파크·액티비티 | I42: 해양·자연 | J42: 바다, 촬영명소 | K42: 중 | M42: Y | N42: 바다 관련 → 보조 해양 | O42: 청보리밭이 섬 전체를 덮는 봄이 절정. 한 바퀴 두 시간이면 돈다. | P42: =IF($H42="숙박",0,IF($H42=MID(P$1,3,20),IF($I42="",1,0.6),IF($I42=MID(P$1,3,20),0.4,0))) -> 0 | Q42: =IF($H42="숙박",0,IF($H42=MID(Q$1,3,20),IF($I42="",1,0.6),IF($I42=MID(Q$1,3,20),0.4,0))) -> 0 | R42: =IF($H42="숙박",0,IF($H42=MID(R$1,3,20),IF($I42="",1,0.6),IF($I42=MID(R$1,3,20),0.4,0))) -> 0.6 | S42: =IF($H42="숙박",0,IF($H42=MID(S$1,3,20),IF($I42="",1,0.6),IF($I42=MID(S$1,3,20),0.4,0))) -> 0 | T42: =IF($H42="숙박",0,IF($H42=MID(T$1,3,20),IF($I42="",1,0.6),IF($I42=MID(T$1,3,20),0.4,0))) -> 0.4 | U42: =IF($H42="숙박",0,IF(ISNUMBER(SEARCH("야경",$J42)),1,0)) -> 0 | V42: =IF($H42="숙박",0,1) -> 1
A43: 42 | B43: 장소 마스터 | D43: 구조라성 | E43: Gujora Fortress | F43: RESCENE Route | G43: 역사·문화 | H43: 역사·문화 | I43: 해양·자연 | J43: 바다, 촬영명소 | K43: 하 | M43: Y | N43: 바다 관련 → 보조 해양 | O43: 조선 수군이 쌓은 산성. 해변 뒤 능선을 따라 성벽이 남아 구조라항과 외도 방향 바다가 한눈에 든다. | P43: =IF($H43="숙박",0,IF($H43=MID(P$1,3,20),IF($I43="",1,0.6),IF($I43=MID(P$1,3,20),0.4,0))) -> 0.6 | Q43: =IF($H43="숙박",0,IF($H43=MID(Q$1,3,20),IF($I43="",1,0.6),IF($I43=MID(Q$1,3,20),0.4,0))) -> 0 | R43: =IF($H43="숙박",0,IF($H43=MID(R$1,3,20),IF($I43="",1,0.6),IF($I43=MID(R$1,3,20),0.4,0))) -> 0 | S43: =IF($H43="숙박",0,IF($H43=MID(S$1,3,20),IF($I43="",1,0.6),IF($I43=MID(S$1,3,20),0.4,0))) -> 0 | T43: =IF($H43="숙박",0,IF($H43=MID(T$1,3,20),IF($I43="",1,0.6),IF($I43=MID(T$1,3,20),0.4,0))) -> 0.4 | U43: =IF($H43="숙박",0,IF(ISNUMBER(SEARCH("야경",$J43)),1,0)) -> 0 | V43: =IF($H43="숙박",0,1) -> 1
A44: 43 | B44: 장소 마스터 | D44: 국립제주박물관 | E44: Jeju National Museum | F44: 제주 K-Drama | G44: 역사·문화 | H44: 역사·문화 | I44: 해양·자연 | J44: 바다, 실내, 촬영명소 | K44: 중 | M44: Y | N44: 바다 관련 → 보조 해양 | O44: 탐라부터 조선까지 섬의 유물을 모았다. 공항에서 가까워 첫날에 넣기 좋다. | P44: =IF($H44="숙박",0,IF($H44=MID(P$1,3,20),IF($I44="",1,0.6),IF($I44=MID(P$1,3,20),0.4,0))) -> 0.6 | Q44: =IF($H44="숙박",0,IF($H44=MID(Q$1,3,20),IF($I44="",1,0.6),IF($I44=MID(Q$1,3,20),0.4,0))) -> 0 | R44: =IF($H44="숙박",0,IF($H44=MID(R$1,3,20),IF($I44="",1,0.6),IF($I44=MID(R$1,3,20),0.4,0))) -> 0 | S44: =IF($H44="숙박",0,IF($H44=MID(S$1,3,20),IF($I44="",1,0.6),IF($I44=MID(S$1,3,20),0.4,0))) -> 0 | T44: =IF($H44="숙박",0,IF($H44=MID(T$1,3,20),IF($I44="",1,0.6),IF($I44=MID(T$1,3,20),0.4,0))) -> 0.4 | U44: =IF($H44="숙박",0,IF(ISNUMBER(SEARCH("야경",$J44)),1,0)) -> 0 | V44: =IF($H44="숙박",0,1) -> 1
A45: 44 | B45: 장소 마스터 | D45: 노들섬 | E45: Nodeul Island | F45: 케이팝 데몬 헌터스 | G45: 테마파크·액티비티 | H45: 테마파크·액티비티 | I45: 해양·자연 | J45: 바다, 실내, 촬영명소 | K45: 중 | M45: Y | N45: 바다 관련 → 보조 해양 | O45: 한강 한가운데의 공연·전시 섬. 보행로로 걸어 들어간다. | P45: =IF($H45="숙박",0,IF($H45=MID(P$1,3,20),IF($I45="",1,0.6),IF($I45=MID(P$1,3,20),0.4,0))) -> 0 | Q45: =IF($H45="숙박",0,IF($H45=MID(Q$1,3,20),IF($I45="",1,0.6),IF($I45=MID(Q$1,3,20),0.4,0))) -> 0 | R45: =IF($H45="숙박",0,IF($H45=MID(R$1,3,20),IF($I45="",1,0.6),IF($I45=MID(R$1,3,20),0.4,0))) -> 0.6 | S45: =IF($H45="숙박",0,IF($H45=MID(S$1,3,20),IF($I45="",1,0.6),IF($I45=MID(S$1,3,20),0.4,0))) -> 0 | T45: =IF($H45="숙박",0,IF($H45=MID(T$1,3,20),IF($I45="",1,0.6),IF($I45=MID(T$1,3,20),0.4,0))) -> 0.4 | U45: =IF($H45="숙박",0,IF(ISNUMBER(SEARCH("야경",$J45)),1,0)) -> 0 | V45: =IF($H45="숙박",0,1) -> 1
A46: 45 | B46: 장소 마스터 | D46: 다대포 꿈의낙조분수 | E46: Dadaepo Sunset Fountain | F46: 부산 영화 기행 | G46: 힐링·생태 | H46: 힐링·생태 | I46: 해양·자연 | J46: 바다, 촬영명소 | K46: 중 | M46: Y | N46: 바다 관련 → 보조 해양 | O46: 해 지는 시간에 맞춰 물을 뿜는 대형 분수. 다대포 해변과 붙어 있다. | P46: =IF($H46="숙박",0,IF($H46=MID(P$1,3,20),IF($I46="",1,0.6),IF($I46=MID(P$1,3,20),0.4,0))) -> 0 | Q46: =IF($H46="숙박",0,IF($H46=MID(Q$1,3,20),IF($I46="",1,0.6),IF($I46=MID(Q$1,3,20),0.4,0))) -> 0.6 | R46: =IF($H46="숙박",0,IF($H46=MID(R$1,3,20),IF($I46="",1,0.6),IF($I46=MID(R$1,3,20),0.4,0))) -> 0 | S46: =IF($H46="숙박",0,IF($H46=MID(S$1,3,20),IF($I46="",1,0.6),IF($I46=MID(S$1,3,20),0.4,0))) -> 0 | T46: =IF($H46="숙박",0,IF($H46=MID(T$1,3,20),IF($I46="",1,0.6),IF($I46=MID(T$1,3,20),0.4,0))) -> 0.4 | U46: =IF($H46="숙박",0,IF(ISNUMBER(SEARCH("야경",$J46)),1,0)) -> 0 | V46: =IF($H46="숙박",0,1) -> 1
A47: 46 | B47: 장소 마스터 | D47: 대포주상절리대 | E47: Daepo Columnar Joints | F47: 제주 K-Drama | G47: 역사·문화 | H47: 역사·문화 | I47: 해양·자연 | J47: 바다, 촬영명소 | K47: 하 | M47: Y | N47: 바다 관련 → 보조 해양 | O47: 육각 기둥이 바다로 늘어선 절벽. 중문 권역에 있다. | P47: =IF($H47="숙박",0,IF($H47=MID(P$1,3,20),IF($I47="",1,0.6),IF($I47=MID(P$1,3,20),0.4,0))) -> 0.6 | Q47: =IF($H47="숙박",0,IF($H47=MID(Q$1,3,20),IF($I47="",1,0.6),IF($I47=MID(Q$1,3,20),0.4,0))) -> 0 | R47: =IF($H47="숙박",0,IF($H47=MID(R$1,3,20),IF($I47="",1,0.6),IF($I47=MID(R$1,3,20),0.4,0))) -> 0 | S47: =IF($H47="숙박",0,IF($H47=MID(S$1,3,20),IF($I47="",1,0.6),IF($I47=MID(S$1,3,20),0.4,0))) -> 0 | T47: =IF($H47="숙박",0,IF($H47=MID(T$1,3,20),IF($I47="",1,0.6),IF($I47=MID(T$1,3,20),0.4,0))) -> 0.4 | U47: =IF($H47="숙박",0,IF(ISNUMBER(SEARCH("야경",$J47)),1,0)) -> 0 | V47: =IF($H47="숙박",0,1) -> 1
A48: 47 | B48: 장소 마스터 | D48: 도두봉 | E48: Dodubong | F48: 제주 K-Drama | G48: 힐링·생태 | H48: 힐링·생태 | I48: 해양·자연 | J48: 바다, 촬영명소 | K48: 상 | M48: Y | N48: 바다 관련 → 보조 해양 | O48: 공항 활주로와 바다가 같이 보이는 낮은 언덕. 비행기 사진 자리로 알려져 있다. | P48: =IF($H48="숙박",0,IF($H48=MID(P$1,3,20),IF($I48="",1,0.6),IF($I48=MID(P$1,3,20),0.4,0))) -> 0 | Q48: =IF($H48="숙박",0,IF($H48=MID(Q$1,3,20),IF($I48="",1,0.6),IF($I48=MID(Q$1,3,20),0.4,0))) -> 0.6 | R48: =IF($H48="숙박",0,IF($H48=MID(R$1,3,20),IF($I48="",1,0.6),IF($I48=MID(R$1,3,20),0.4,0))) -> 0 | S48: =IF($H48="숙박",0,IF($H48=MID(S$1,3,20),IF($I48="",1,0.6),IF($I48=MID(S$1,3,20),0.4,0))) -> 0 | T48: =IF($H48="숙박",0,IF($H48=MID(T$1,3,20),IF($I48="",1,0.6),IF($I48=MID(T$1,3,20),0.4,0))) -> 0.4 | U48: =IF($H48="숙박",0,IF(ISNUMBER(SEARCH("야경",$J48)),1,0)) -> 0 | V48: =IF($H48="숙박",0,1) -> 1
A49: 48 | B49: 장소 마스터 | D49: 마라도 | E49: Marado Island | F49: 제주 K-Drama | G49: 테마파크·액티비티 | H49: 테마파크·액티비티 | I49: 해양·자연 | J49: 바다, 촬영명소 | K49: 중 | M49: Y | N49: 바다 관련 → 보조 해양 | O49: 국토 최남단 섬. 배 시간이 정해져 있어 체류 시간이 짧다. | P49: =IF($H49="숙박",0,IF($H49=MID(P$1,3,20),IF($I49="",1,0.6),IF($I49=MID(P$1,3,20),0.4,0))) -> 0 | Q49: =IF($H49="숙박",0,IF($H49=MID(Q$1,3,20),IF($I49="",1,0.6),IF($I49=MID(Q$1,3,20),0.4,0))) -> 0 | R49: =IF($H49="숙박",0,IF($H49=MID(R$1,3,20),IF($I49="",1,0.6),IF($I49=MID(R$1,3,20),0.4,0))) -> 0.6 | S49: =IF($H49="숙박",0,IF($H49=MID(S$1,3,20),IF($I49="",1,0.6),IF($I49=MID(S$1,3,20),0.4,0))) -> 0 | T49: =IF($H49="숙박",0,IF($H49=MID(T$1,3,20),IF($I49="",1,0.6),IF($I49=MID(T$1,3,20),0.4,0))) -> 0.4 | U49: =IF($H49="숙박",0,IF(ISNUMBER(SEARCH("야경",$J49)),1,0)) -> 0 | V49: =IF($H49="숙박",0,1) -> 1
A50: 49 | B50: 장소 마스터 | D50: 마린시티 | E50: Marine City | F50: 부산 영화 기행 | G50: 로컬·먹거리 | H50: 로컬·먹거리 | I50: 해양·자연 | J50: 바다, 야경, 촬영명소 | K50: 중 | M50: Y | N50: 바다 관련 → 보조 해양 | O50: 초고층 주거단지 앞 해안 산책로와 식당가. 광안대교 야경이 정면이다. | P50: =IF($H50="숙박",0,IF($H50=MID(P$1,3,20),IF($I50="",1,0.6),IF($I50=MID(P$1,3,20),0.4,0))) -> 0 | Q50: =IF($H50="숙박",0,IF($H50=MID(Q$1,3,20),IF($I50="",1,0.6),IF($I50=MID(Q$1,3,20),0.4,0))) -> 0 | R50: =IF($H50="숙박",0,IF($H50=MID(R$1,3,20),IF($I50="",1,0.6),IF($I50=MID(R$1,3,20),0.4,0))) -> 0 | S50: =IF($H50="숙박",0,IF($H50=MID(S$1,3,20),IF($I50="",1,0.6),IF($I50=MID(S$1,3,20),0.4,0))) -> 0.6 | T50: =IF($H50="숙박",0,IF($H50=MID(T$1,3,20),IF($I50="",1,0.6),IF($I50=MID(T$1,3,20),0.4,0))) -> 0.4 | U50: =IF($H50="숙박",0,IF(ISNUMBER(SEARCH("야경",$J50)),1,0)) -> 1 | V50: =IF($H50="숙박",0,1) -> 1
A51: 50 | B51: 장소 마스터 | D51: 부산 용두산공원 · 부산타워 | E51: Yongdusan Park & Busan Tower | F51: 부산 영화 기행 | G51: 힐링·생태 | H51: 힐링·생태 | I51: 해양·자연 | J51: 바다, 야경, 촬영명소 | K51: 중 | M51: Y | N51: 바다 관련 → 보조 해양 | O51: 남포동 위 언덕의 공원. 타워에서 항구와 영도가 함께 보인다. | P51: =IF($H51="숙박",0,IF($H51=MID(P$1,3,20),IF($I51="",1,0.6),IF($I51=MID(P$1,3,20),0.4,0))) -> 0 | Q51: =IF($H51="숙박",0,IF($H51=MID(Q$1,3,20),IF($I51="",1,0.6),IF($I51=MID(Q$1,3,20),0.4,0))) -> 0.6 | R51: =IF($H51="숙박",0,IF($H51=MID(R$1,3,20),IF($I51="",1,0.6),IF($I51=MID(R$1,3,20),0.4,0))) -> 0 | S51: =IF($H51="숙박",0,IF($H51=MID(S$1,3,20),IF($I51="",1,0.6),IF($I51=MID(S$1,3,20),0.4,0))) -> 0 | T51: =IF($H51="숙박",0,IF($H51=MID(T$1,3,20),IF($I51="",1,0.6),IF($I51=MID(T$1,3,20),0.4,0))) -> 0.4 | U51: =IF($H51="숙박",0,IF(ISNUMBER(SEARCH("야경",$J51)),1,0)) -> 1 | V51: =IF($H51="숙박",0,1) -> 1
A52: 51 | B52: 장소 마스터 | D52: 블루라인파크 미포정거장 | E52: Blueline Park Mipo Station | F52: 부산 영화 기행 | G52: 테마파크·액티비티 | H52: 테마파크·액티비티 | I52: 해양·자연 | J52: 바다, 촬영명소 | K52: 하 | M52: Y | N52: 바다 관련 → 보조 해양 | O52: 해변열차와 스카이캡슐이 출발하는 정거장. 청사포·송정으로 이어진다. | P52: =IF($H52="숙박",0,IF($H52=MID(P$1,3,20),IF($I52="",1,0.6),IF($I52=MID(P$1,3,20),0.4,0))) -> 0 | Q52: =IF($H52="숙박",0,IF($H52=MID(Q$1,3,20),IF($I52="",1,0.6),IF($I52=MID(Q$1,3,20),0.4,0))) -> 0 | R52: =IF($H52="숙박",0,IF($H52=MID(R$1,3,20),IF($I52="",1,0.6),IF($I52=MID(R$1,3,20),0.4,0))) -> 0.6 | S52: =IF($H52="숙박",0,IF($H52=MID(S$1,3,20),IF($I52="",1,0.6),IF($I52=MID(S$1,3,20),0.4,0))) -> 0 | T52: =IF($H52="숙박",0,IF($H52=MID(T$1,3,20),IF($I52="",1,0.6),IF($I52=MID(T$1,3,20),0.4,0))) -> 0.4 | U52: =IF($H52="숙박",0,IF(ISNUMBER(SEARCH("야경",$J52)),1,0)) -> 0 | V52: =IF($H52="숙박",0,1) -> 1
A53: 52 | B53: 장소 마스터 | D53: 산방산 | E53: Sanbangsan | F53: 제주 K-Drama | G53: 역사·문화 | H53: 역사·문화 | I53: 해양·자연 | J53: 바다, 촬영명소 | K53: 상 | M53: Y | N53: 바다 관련 → 보조 해양 | O53: 바다 옆에 솟은 종상화산. 중턱의 산방굴사까지 계단이 놓여 있다. | P53: =IF($H53="숙박",0,IF($H53=MID(P$1,3,20),IF($I53="",1,0.6),IF($I53=MID(P$1,3,20),0.4,0))) -> 0.6 | Q53: =IF($H53="숙박",0,IF($H53=MID(Q$1,3,20),IF($I53="",1,0.6),IF($I53=MID(Q$1,3,20),0.4,0))) -> 0 | R53: =IF($H53="숙박",0,IF($H53=MID(R$1,3,20),IF($I53="",1,0.6),IF($I53=MID(R$1,3,20),0.4,0))) -> 0 | S53: =IF($H53="숙박",0,IF($H53=MID(S$1,3,20),IF($I53="",1,0.6),IF($I53=MID(S$1,3,20),0.4,0))) -> 0 | T53: =IF($H53="숙박",0,IF($H53=MID(T$1,3,20),IF($I53="",1,0.6),IF($I53=MID(T$1,3,20),0.4,0))) -> 0.4 | U53: =IF($H53="숙박",0,IF(ISNUMBER(SEARCH("야경",$J53)),1,0)) -> 0 | V53: =IF($H53="숙박",0,1) -> 1
... A74: 73 | B74: 테마 파일 (부산 영화 기행) | D74: 흰여울문화마을 | E74: Huinnyeoul Culture Village | F74: 부산 영화 기행 | G74: 힐링·생태 | H74: 힐링·생태 | I74: 해양·자연 | J74: 바다, 촬영명소 | K74: 중 | M74: Y | N74: 바다 관련 → 보조 해양 | O74: 영도 절벽 위로 난 좁은 길. 흰 담과 파란 바다가 붙어 있어 여러 작품이 같은 구도를 반복해 썼다. | P74: =IF($H74="숙박",0,IF($H74=MID(P$1,3,20),IF($I74="",1,0.6),IF($I74=MID(P$1,3,20),0.4,0))) -> 0 | Q74: =IF($H74="숙박",0,IF($H74=MID(Q$1,3,20),IF($I74="",1,0.6),IF($I74=MID(Q$1,3,20),0.4,0))) -> 0.6 | R74: =IF($H74="숙박",0,IF($H74=MID(R$1,3,20),IF($I74="",1,0.6),IF($I74=MID(R$1,3,20),0.4,0))) -> 0 | S74: =IF($H74="숙박",0,IF($H74=MID(S$1,3,20),IF($I74="",1,0.6),IF($I74=MID(S$1,3,20),0.4,0))) -> 0 | T74: =IF($H74="숙박",0,IF($H74=MID(T$1,3,20),IF($I74="",1,0.6),IF($I74=MID(T$1,3,20),0.4,0))) -> 0.4 | U74: =IF($H74="숙박",0,IF(ISNUMBER(SEARCH("야경",$J74)),1,0)) -> 0 | V74: =IF($H74="숙박",0,1) -> 1
A75: 74 | B75: 장소 마스터 | C75: 논산 | D75: 강경 근대역사거리 | E75: Ganggyeong Historic Street | G75: 역사·문화 | H75: 역사·문화 | I75: 해양·자연 | J75: 바다 | K75: 하 | M75: Y | N75: 바다 관련 → 보조 해양 | O75: 금강 포구 시절의 창고와 은행 건물이 남은 거리. | P75: =IF($H75="숙박",0,IF($H75=MID(P$1,3,20),IF($I75="",1,0.6),IF($I75=MID(P$1,3,20),0.4,0))) -> 0.6 | Q75: =IF($H75="숙박",0,IF($H75=MID(Q$1,3,20),IF($I75="",1,0.6),IF($I75=MID(Q$1,3,20),0.4,0))) -> 0 | R75: =IF($H75="숙박",0,IF($H75=MID(R$1,3,20),IF($I75="",1,0.6),IF($I75=MID(R$1,3,20),0.4,0))) -> 0 | S75: =IF($H75="숙박",0,IF($H75=MID(S$1,3,20),IF($I75="",1,0.6),IF($I75=MID(S$1,3,20),0.4,0))) -> 0 | T75: =IF($H75="숙박",0,IF($H75=MID(T$1,3,20),IF($I75="",1,0.6),IF($I75=MID(T$1,3,20),0.4,0))) -> 0.4 | U75: =IF($H75="숙박",0,IF(ISNUMBER(SEARCH("야경",$J75)),1,0)) -> 0 | V75: =IF($H75="숙박",0,1) -> 1
A76: 75 | B76: 장소 마스터 | C76: 통영 | D76: 강구안 | E76: Gangguan | G76: 힐링·생태 | H76: 힐링·생태 | I76: 해양·자연 | J76: 바다 | K76: 중 | M76: Y | N76: 바다 관련 → 보조 해양 | O76: 어선이 드나드는 도심 포구. 거북선 모형이 떠 있다. | P76: =IF($H76="숙박",0,IF($H76=MID(P$1,3,20),IF($I76="",1,0.6),IF($I76=MID(P$1,3,20),0.4,0))) -> 0 | Q76: =IF($H76="숙박",0,IF($H76=MID(Q$1,3,20),IF($I76="",1,0.6),IF($I76=MID(Q$1,3,20),0.4,0))) -> 0.6 | R76: =IF($H76="숙박",0,IF($H76=MID(R$1,3,20),IF($I76="",1,0.6),IF($I76=MID(R$1,3,20),0.4,0))) -> 0 | S76: =IF($H76="숙박",0,IF($H76=MID(S$1,3,20),IF($I76="",1,0.6),IF($I76=MID(S$1,3,20),0.4,0))) -> 0 | T76: =IF($H76="숙박",0,IF($H76=MID(T$1,3,20),IF($I76="",1,0.6),IF($I76=MID(T$1,3,20),0.4,0))) -> 0.4 | U76: =IF($H76="숙박",0,IF(ISNUMBER(SEARCH("야경",$J76)),1,0)) -> 0 | V76: =IF($H76="숙박",0,1) -> 1
A77: 76 | B77: 장소 마스터 | C77: 인천 | D77: 강화 광성보 | E77: Gwangseongbo Fort | G77: 역사·문화 | H77: 역사·문화 | I77: 해양·자연 | J77: 바다 | K77: 중 | M77: Y | N77: 바다 관련 → 보조 해양 | O77: 신미양요의 격전지. 돈대와 성벽이 해안을 따라 남아 있다. | P77: =IF($H77="숙박",0,IF($H77=MID(P$1,3,20),IF($I77="",1,0.6),IF($I77=MID(P$1,3,20),0.4,0))) -> 0.6 | Q77: =IF($H77="숙박",0,IF($H77=MID(Q$1,3,20),IF($I77="",1,0.6),IF($I77=MID(Q$1,3,20),0.4,0))) -> 0 | R77: =IF($H77="숙박",0,IF($H77=MID(R$1,3,20),IF($I77="",1,0.6),IF($I77=MID(R$1,3,20),0.4,0))) -> 0 | S77: =IF($H77="숙박",0,IF($H77=MID(S$1,3,20),IF($I77="",1,0.6),IF($I77=MID(S$1,3,20),0.4,0))) -> 0 | T77: =IF($H77="숙박",0,IF($H77=MID(T$1,3,20),IF($I77="",1,0.6),IF($I77=MID(T$1,3,20),0.4,0))) -> 0.4 | U77: =IF($H77="숙박",0,IF(ISNUMBER(SEARCH("야경",$J77)),1,0)) -> 0 | V77: =IF($H77="숙박",0,1) -> 1
A78: 77 | B78: 장소 마스터 | C78: 강릉 | D78: 경포호 | E78: Gyeongpo Lake | G78: 힐링·생태 | H78: 힐링·생태 | I78: 해양·자연 | J78: 바다 | K78: 중 | M78: Y | N78: 바다 관련 → 보조 해양 | O78: 해변 뒤 석호. 둘레 4.3km 산책로가 돈다. | P78: =IF($H78="숙박",0,IF($H78=MID(P$1,3,20),IF($I78="",1,0.6),IF($I78=MID(P$1,3,20),0.4,0))) -> 0 | Q78: =IF($H78="숙박",0,IF($H78=MID(Q$1,3,20),IF($I78="",1,0.6),IF($I78=MID(Q$1,3,20),0.4,0))) -> 0.6 | R78: =IF($H78="숙박",0,IF($H78=MID(R$1,3,20),IF($I78="",1,0.6),IF($I78=MID(R$1,3,20),0.4,0))) -> 0 | S78: =IF($H78="숙박",0,IF($H78=MID(S$1,3,20),IF($I78="",1,0.6),IF($I78=MID(S$1,3,20),0.4,0))) -> 0 | T78: =IF($H78="숙박",0,IF($H78=MID(T$1,3,20),IF($I78="",1,0.6),IF($I78=MID(T$1,3,20),0.4,0))) -> 0.4 | U78: =IF($H78="숙박",0,IF(ISNUMBER(SEARCH("야경",$J78)),1,0)) -> 0 | V78: =IF($H78="숙박",0,1) -> 1
A79: 78 | B79: 장소 마스터 | D79: 공산성 권역 한옥 | E79: Gongsanseong hanok stays | H79: 역사·문화 | K79: 하 | M79: Y | N79: 원래 분류 없음 → 규칙으로 채움 | P79: =IF($H79="숙박",0,IF($H79=MID(P$1,3,20),IF($I79="",1,0.6),IF($I79=MID(P$1,3,20),0.4,0))) -> 1 | Q79: =IF($H79="숙박",0,IF($H79=MID(Q$1,3,20),IF($I79="",1,0.6),IF($I79=MID(Q$1,3,20),0.4,0))) -> 0 | R79: =IF($H79="숙박",0,IF($H79=MID(R$1,3,20),IF($I79="",1,0.6),IF($I79=MID(R$1,3,20),0.4,0))) -> 0 | S79: =IF($H79="숙박",0,IF($H79=MID(S$1,3,20),IF($I79="",1,0.6),IF($I79=MID(S$1,3,20),0.4,0))) -> 0 | T79: =IF($H79="숙박",0,IF($H79=MID(T$1,3,20),IF($I79="",1,0.6),IF($I79=MID(T$1,3,20),0.4,0))) -> 0 | U79: =IF($H79="숙박",0,IF(ISNUMBER(SEARCH("야경",$J79)),1,0)) -> 0 | V79: =IF($H79="숙박",0,1) -> 1
A80: 79 | B80: 장소 마스터 | D80: 광한루 권역 한옥 | E80: Gwanghallu hanok stays | H80: 역사·문화 | K80: 하 | M80: Y | N80: 원래 분류 없음 → 규칙으로 채움 | P80: =IF($H80="숙박",0,IF($H80=MID(P$1,3,20),IF($I80="",1,0.6),IF($I80=MID(P$1,3,20),0.4,0))) -> 1 | Q80: =IF($H80="숙박",0,IF($H80=MID(Q$1,3,20),IF($I80="",1,0.6),IF($I80=MID(Q$1,3,20),0.4,0))) -> 0 | R80: =IF($H80="숙박",0,IF($H80=MID(R$1,3,20),IF($I80="",1,0.6),IF($I80=MID(R$1,3,20),0.4,0))) -> 0 | S80: =IF($H80="숙박",0,IF($H80=MID(S$1,3,20),IF($I80="",1,0.6),IF($I80=MID(S$1,3,20),0.4,0))) -> 0 | T80: =IF($H80="숙박",0,IF($H80=MID(T$1,3,20),IF($I80="",1,0.6),IF($I80=MID(T$1,3,20),0.4,0))) -> 0 | U80: =IF($H80="숙박",0,IF(ISNUMBER(SEARCH("야경",$J80)),1,0)) -> 0 | V80: =IF($H80="숙박",0,1) -> 1
A81: 80 | B81: 장소 마스터 | C81: 포항 | D81: 구룡포 근대문화역사거리 | E81: Guryongpo Modern History Street | G81: 역사·문화 | H81: 역사·문화 | I81: 해양·자연 | J81: 바다 | K81: 하 | M81: Y | N81: 바다 관련 → 보조 해양 | O81: 일본식 가옥이 남은 항구 거리. | P81: =IF($H81="숙박",0,IF($H81=MID(P$1,3,20),IF($I81="",1,0.6),IF($I81=MID(P$1,3,20),0.4,0))) -> 0.6 | Q81: =IF($H81="숙박",0,IF($H81=MID(Q$1,3,20),IF($I81="",1,0.6),IF($I81=MID(Q$1,3,20),0.4,0))) -> 0 | R81: =IF($H81="숙박",0,IF($H81=MID(R$1,3,20),IF($I81="",1,0.6),IF($I81=MID(R$1,3,20),0.4,0))) -> 0 | S81: =IF($H81="숙박",0,IF($H81=MID(S$1,3,20),IF($I81="",1,0.6),IF($I81=MID(S$1,3,20),0.4,0))) -> 0 | T81: =IF($H81="숙박",0,IF($H81=MID(T$1,3,20),IF($I81="",1,0.6),IF($I81=MID(T$1,3,20),0.4,0))) -> 0.4 | U81: =IF($H81="숙박",0,IF(ISNUMBER(SEARCH("야경",$J81)),1,0)) -> 0 | V81: =IF($H81="숙박",0,1) -> 1
A82: 81 | B82: 장소 마스터 | C82: 거제 | D82: 근포동굴 | E82: Geunpo Cave | G82: 테마파크·액티비티 | H82: 테마파크·액티비티 | I82: 해양·자연 | J82: 바다 | K82: 하 | M82: Y | N82: 바다 관련 → 보조 해양 | O82: 일제강점기에 판 굴. 바다로 난 프레임이 된다. | P82: =IF($H82="숙박",0,IF($H82=MID(P$1,3,20),IF($I82="",1,0.6),IF($I82=MID(P$1,3,20),0.4,0))) -> 0 | Q82: =IF($H82="숙박",0,IF($H82=MID(Q$1,3,20),IF($I82="",1,0.6),IF($I82=MID(Q$1,3,20),0.4,0))) -> 0 | R82: =IF($H82="숙박",0,IF($H82=MID(R$1,3,20),IF($I82="",1,0.6),IF($I82=MID(R$1,3,20),0.4,0))) -> 0.6 | S82: =IF($H82="숙박",0,IF($H82=MID(S$1,3,20),IF($I82="",1,0.6),IF($I82=MID(S$1,3,20),0.4,0))) -> 0 | T82: =IF($H82="숙박",0,IF($H82=MID(T$1,3,20),IF($I82="",1,0.6),IF($I82=MID(T$1,3,20),0.4,0))) -> 0.4 | U82: =IF($H82="숙박",0,IF(ISNUMBER(SEARCH("야경",$J82)),1,0)) -> 0 | V82: =IF($H82="숙박",0,1) -> 1
A83: 82 | B83: 장소 마스터 | C83: 여수 | D83: 금오도 비렁길 | E83: Geumodo Cliff Trail | G83: 힐링·생태 | H83: 힐링·생태 | I83: 해양·자연 | J83: 바다 | K83: 중 | M83: Y | N83: 바다 관련 → 보조 해양 | O83: 벼랑을 따라 이어지는 섬 해안길. | P83: =IF($H83="숙박",0,IF($H83=MID(P$1,3,20),IF($I83="",1,0.6),IF($I83=MID(P$1,3,20),0.4,0))) -> 0 | Q83: =IF($H83="숙박",0,IF($H83=MID(Q$1,3,20),IF($I83="",1,0.6),IF($I83=MID(Q$1,3,20),0.4,0))) -> 0.6 | R83: =IF($H83="숙박",0,IF($H83=MID(R$1,3,20),IF($I83="",1,0.6),IF($I83=MID(R$1,3,20),0.4,0))) -> 0 | S83: =IF($H83="숙박",0,IF($H83=MID(S$1,3,20),IF($I83="",1,0.6),IF($I83=MID(S$1,3,20),0.4,0))) -> 0 | T83: =IF($H83="숙박",0,IF($H83=MID(T$1,3,20),IF($I83="",1,0.6),IF($I83=MID(T$1,3,20),0.4,0))) -> 0.4 | U83: =IF($H83="숙박",0,IF(ISNUMBER(SEARCH("야경",$J83)),1,0)) -> 0 | V83: =IF($H83="숙박",0,1) -> 1
...

Sheet 테마 프로필
A1: 테마별 카테고리 구성비 — 새 방식(주 0.6 + 보조 0.4)과 기존 앱 분류 비교
A3: 테마 | B3: 장소 수 | C3: 새: 역사·문화 | D3: 새: 힐링·생태 | E3: 새: 테마파크·액티비티 | F3: 새: 로컬·먹거리 | G3: 새: 해양·자연 | H3: 새: 야경 비중 | I3: 기존: 역사·문화 | J3: 기존: 힐링·생태 | K3: 기존: 테마파크·액티비티 | L3: 기존: 로컬·먹거리 | M3: 기존: 해양·자연
A4: 왕과 사는 남자 | B4: =SUMIFS('장소 분류'!$V:$V,'장소 분류'!$F:$F,"*"&$A4&"*") -> 18 | C4: =SUMIFS('장소 분류'!P:P,'장소 분류'!$F:$F,"*"&$A4&"*")/$B4 -> 0.4 | D4: =SUMIFS('장소 분류'!Q:Q,'장소 분류'!$F:$F,"*"&$A4&"*")/$B4 -> 0.31111111 | E4: =SUMIFS('장소 분류'!R:R,'장소 분류'!$F:$F,"*"&$A4&"*")/$B4 -> 0.23333333 | F4: =SUMIFS('장소 분류'!S:S,'장소 분류'!$F:$F,"*"&$A4&"*")/$B4 -> 0.055555556 | G4: =SUMIFS('장소 분류'!T:T,'장소 분류'!$F:$F,"*"&$A4&"*")/$B4 -> 0 | H4: =SUMIFS('장소 분류'!U:U,'장소 분류'!$F:$F,"*"&$A4&"*")/$B4 -> 0.055555556 | I4: 0.3333 | J4: 0.3333 | K4: 0.2778 | L4: 0.0556 | M4: 0
A5: 케이팝 데몬 헌터스 | B5: =SUMIFS('장소 분류'!$V:$V,'장소 분류'!$F:$F,"*"&$A5&"*") -> 86 | C5: =SUMIFS('장소 분류'!P:P,'장소 분류'!$F:$F,"*"&$A5&"*")/$B5 -> 0.29302326 | D5: =SUMIFS('장소 분류'!Q:Q,'장소 분류'!$F:$F,"*"&$A5&"*")/$B5 -> 0.22790698 | E5: =SUMIFS('장소 분류'!R:R,'장소 분류'!$F:$F,"*"&$A5&"*")/$B5 -> 0.21627907 | F5: =SUMIFS('장소 분류'!S:S,'장소 분류'!$F:$F,"*"&$A5&"*")/$B5 -> 0.25348837 | G5: =SUMIFS('장소 분류'!T:T,'장소 분류'!$F:$F,"*"&$A5&"*")/$B5 -> 0.0093023256 | H5: =SUMIFS('장소 분류'!U:U,'장소 분류'!$F:$F,"*"&$A5&"*")/$B5 -> 0.12790698 | I5: 0.3023 | J5: 0.2093 | K5: 0.2209 | L5: 0.2674 | M5: 0
A6: RESCENE Route | B6: =SUMIFS('장소 분류'!$V:$V,'장소 분류'!$F:$F,"*"&$A6&"*") -> 86 | C6: =SUMIFS('장소 분류'!P:P,'장소 분류'!$F:$F,"*"&$A6&"*")/$B6 -> 0.32790698 | D6: =SUMIFS('장소 분류'!Q:Q,'장소 분류'!$F:$F,"*"&$A6&"*")/$B6 -> 0.16511628 | E6: =SUMIFS('장소 분류'!R:R,'장소 분류'!$F:$F,"*"&$A6&"*")/$B6 -> 0.13023256 | F6: =SUMIFS('장소 분류'!S:S,'장소 분류'!$F:$F,"*"&$A6&"*")/$B6 -> 0.19302326 | G6: =SUMIFS('장소 분류'!T:T,'장소 분류'!$F:$F,"*"&$A6&"*")/$B6 -> 0.18372093 | H6: =SUMIFS('장소 분류'!U:U,'장소 분류'!$F:$F,"*"&$A6&"*")/$B6 -> 0.058139535 | I6: 0.2907 | J6: 0.1744 | K6: 0.1395 | L6: 0.1977 | M6: 0.1977
A7: 제주 K-Drama | B7: =SUMIFS('장소 분류'!$V:$V,'장소 분류'!$F:$F,"*"&$A7&"*") -> 81 | C7: =SUMIFS('장소 분류'!P:P,'장소 분류'!$F:$F,"*"&$A7&"*")/$B7 -> 0.1654321 | D7: =SUMIFS('장소 분류'!Q:Q,'장소 분류'!$F:$F,"*"&$A7&"*")/$B7 -> 0.43703704 | E7: =SUMIFS('장소 분류'!R:R,'장소 분류'!$F:$F,"*"&$A7&"*")/$B7 -> 0.083950617 | F7: =SUMIFS('장소 분류'!S:S,'장소 분류'!$F:$F,"*"&$A7&"*")/$B7 -> 0.051851852 | G7: =SUMIFS('장소 분류'!T:T,'장소 분류'!$F:$F,"*"&$A7&"*")/$B7 -> 0.2617284 | H7: =SUMIFS('장소 분류'!U:U,'장소 분류'!$F:$F,"*"&$A7&"*")/$B7 -> 0.037037037 | I7: 0.1852 | J7: 0.6296 | K7: 0.1235 | L7: 0.0617 | M7: 0
A8: 부산 영화 기행 | B8: =SUMIFS('장소 분류'!$V:$V,'장소 분류'!$F:$F,"*"&$A8&"*") -> 71 | C8: =SUMIFS('장소 분류'!P:P,'장소 분류'!$F:$F,"*"&$A8&"*")/$B8 -> 0.14084507 | D8: =SUMIFS('장소 분류'!Q:Q,'장소 분류'!$F:$F,"*"&$A8&"*")/$B8 -> 0.24507042 | E8: =SUMIFS('장소 분류'!R:R,'장소 분류'!$F:$F,"*"&$A8&"*")/$B8 -> 0.15211268 | F8: =SUMIFS('장소 분류'!S:S,'장소 분류'!$F:$F,"*"&$A8&"*")/$B8 -> 0.26478873 | G8: =SUMIFS('장소 분류'!T:T,'장소 분류'!$F:$F,"*"&$A8&"*")/$B8 -> 0.1971831 | H8: =SUMIFS('장소 분류'!U:U,'장소 분류'!$F:$F,"*"&$A8&"*")/$B8 -> 0.14084507 | I8: 0.1408 | J8: 0.4085 | K8: 0.169 | L8: 0.2817 | M8: 0
A10: 기존 값은 앱 테마 파일(.dc.html)의 cat 코드를 센 값(고정값). 새 값은 「장소 분류」 시트에서 자동 계산.

Sheet 군집 적합
A1: 군집 × 테마 적합 점수 = 테마 구성비 × 군집 카테고리 가중치 (SUMPRODUCT)
A2: 노란 칸 가중치는 가설값(문항 구성안 6-2). 군집 산출 시나리오 3단계에서 데이터 기반 값으로 교체.
A4: 군집 | B4: 역사·문화 | C4: 힐링·생태 | D4: 테마파크·액티비티 | E4: 로컬·먹거리 | F4: 해양·자연
A5: C1 MZ 트렌드 | B5: 0.1 | C5: 0.1 | D5: 0.3 | E5: 0.3 | F5: 0.2
A6: C2 커플 감성 | B6: 0.1 | C6: 0.2 | D6: 0.1 | E6: 0.3 | F6: 0.3
A7: C3 키즈 가족 | B7: 0.1 | C7: 0.1 | D7: 0.5 | E7: 0.1 | F7: 0.2
A8: C4 액티브 시니어 | B8: 0.5 | C8: 0.3 | D8: 0.05 | E8: 0.15 | F8: 0
A9: C5 나홀로 힐링 | B9: 0.1 | C9: 0.6 | D9: 0 | E9: 0.1 | F9: 0.2
A10: C6 미식 로컬 | B10: 0.2 | C10: 0.05 | D10: 0.05 | E10: 0.7 | F10: 0
A11: C7 외래객 K-컬처 | B11: 0.3 | C11: 0.05 | D11: 0.2 | E11: 0.3 | F11: 0.15
A12: C8 외래객 웰니스 | B12: 0.1 | C12: 0.3 | D12: 0 | E12: 0.4 | F12: 0.2
A15: 군집 | B15: 왕과 사는 남자 | C15: 케이팝 데몬 헌터스 | D15: RESCENE Route | E15: 제주 K-Drama | F15: 부산 영화 기행
A16: C1 MZ 트렌드 | B16: =SUMPRODUCT(B5:F5,'테마 프로필'!C4:G4) -> 0.15777778 | C16: =SUMPRODUCT(B5:F5,'테마 프로필'!C5:G5) -> 0.19488372 | D16: =SUMPRODUCT(B5:F5,'테마 프로필'!C6:G6) -> 0.18302326 | E16: =SUMPRODUCT(B5:F5,'테마 프로필'!C7:G7) -> 0.15333333 | F16: =SUMPRODUCT(B5:F5,'테마 프로필'!C8:G8) -> 0.20309859
A17: C2 커플 감성 | B17: =SUMPRODUCT(B6:F6,'테마 프로필'!C4:G4) -> 0.14222222 | C17: =SUMPRODUCT(B6:F6,'테마 프로필'!C5:G5) -> 0.17534884 | D17: =SUMPRODUCT(B6:F6,'테마 프로필'!C6:G6) -> 0.19186047 | E17: =SUMPRODUCT(B6:F6,'테마 프로필'!C7:G7) -> 0.20641975 | F17: =SUMPRODUCT(B6:F6,'테마 프로필'!C8:G8) -> 0.21690141
A18: C3 키즈 가족 | B18: =SUMPRODUCT(B7:F7,'테마 프로필'!C4:G4) -> 0.19333333 | C18: =SUMPRODUCT(B7:F7,'테마 프로필'!C5:G5) -> 0.18744186 | D18: =SUMPRODUCT(B7:F7,'테마 프로필'!C6:G6) -> 0.17046512 | E18: =SUMPRODUCT(B7:F7,'테마 프로필'!C7:G7) -> 0.15975309 | F18: =SUMPRODUCT(B7:F7,'테마 프로필'!C8:G8) -> 0.18056338
A19: C4 액티브 시니어 | B19: =SUMPRODUCT(B8:F8,'테마 프로필'!C4:G4) -> 0.31333333 | C19: =SUMPRODUCT(B8:F8,'테마 프로필'!C5:G5) -> 0.26372093 | D19: =SUMPRODUCT(B8:F8,'테마 프로필'!C6:G6) -> 0.24895349 | E19: =SUMPRODUCT(B8:F8,'테마 프로필'!C7:G7) -> 0.22580247 | F19: =SUMPRODUCT(B8:F8,'테마 프로필'!C8:G8) -> 0.19126761
A20: C5 나홀로 힐링 | B20: =SUMPRODUCT(B9:F9,'테마 프로필'!C4:G4) -> 0.23222222 | C20: =SUMPRODUCT(B9:F9,'테마 프로필'!C5:G5) -> 0.19325581 | D20: =SUMPRODUCT(B9:F9,'테마 프로필'!C6:G6) -> 0.18790698 | E20: =SUMPRODUCT(B9:F9,'테마 프로필'!C7:G7) -> 0.3362963 | F20: =SUMPRODUCT(B9:F9,'테마 프로필'!C8:G8) -> 0.22704225
A21: C6 미식 로컬 | B21: =SUMPRODUCT(B10:F10,'테마 프로필'!C4:G4) -> 0.14611111 | C21: =SUMPRODUCT(B10:F10,'테마 프로필'!C5:G5) -> 0.25825581 | D21: =SUMPRODUCT(B10:F10,'테마 프로필'!C6:G6) -> 0.21546512 | E21: =SUMPRODUCT(B10:F10,'테마 프로필'!C7:G7) -> 0.095432099 | F21: =SUMPRODUCT(B10:F10,'테마 프로필'!C8:G8) -> 0.23338028
A22: C7 외래객 K-컬처 | B22: =SUMPRODUCT(B11:F11,'테마 프로필'!C4:G4) -> 0.19888889 | C22: =SUMPRODUCT(B11:F11,'테마 프로필'!C5:G5) -> 0.22 | D22: =SUMPRODUCT(B11:F11,'테마 프로필'!C6:G6) -> 0.21813953 | E22: =SUMPRODUCT(B11:F11,'테마 프로필'!C7:G7) -> 0.14308642 | F22: =SUMPRODUCT(B11:F11,'테마 프로필'!C8:G8) -> 0.19394366
A23: C8 외래객 웰니스 | B23: =SUMPRODUCT(B12:F12,'테마 프로필'!C4:G4) -> 0.15555556 | C23: =SUMPRODUCT(B12:F12,'테마 프로필'!C5:G5) -> 0.20093023 | D23: =SUMPRODUCT(B12:F12,'테마 프로필'!C6:G6) -> 0.19627907 | E23: =SUMPRODUCT(B12:F12,'테마 프로필'!C7:G7) -> 0.22074074 | F23: =SUMPRODUCT(B12:F12,'테마 프로필'!C8:G8) -> 0.23295775

Sheet 가상 새 테마
A1: 가상 새 테마 3개 — 장소별 주·보조 카테고리와 야경 태그 (문항 구성안 7장)
A3: 가상 테마 | B3: 장소 | C3: 주 카테고리 | D3: 보조 카테고리 | E3: 태그
A4: 통영·남해 섬 로맨스 | B4: 소매물도 | C4: 해양·자연 | D4: 힐링·생태
A5: 통영·남해 섬 로맨스 | B5: 한산도 제승당 | C5: 역사·문화 | D5: 해양·자연
A6: 통영·남해 섬 로맨스 | B6: 동피랑 벽화마을 | C6: 힐링·생태 | D6: 역사·문화 | E6: 야경
A7: 통영·남해 섬 로맨스 | B7: 통영 케이블카 | C7: 테마파크·액티비티 | D7: 해양·자연
A8: 통영·남해 섬 로맨스 | B8: 남해 다랭이마을 | C8: 힐링·생태 | D8: 해양·자연
A9: 통영·남해 섬 로맨스 | B9: 남해 독일마을 | C9: 역사·문화 | D9: 힐링·생태
A10: 통영·남해 섬 로맨스 | B10: 상주은모래비치 | C10: 해양·자연 | D10: 힐링·생태
A11: 통영·남해 섬 로맨스 | B11: 통영 중앙시장 | C11: 로컬·먹거리 | D11: 해양·자연
A12: 통영·남해 섬 로맨스 | B12: 강구안 야경 산책 | C12: 해양·자연 | D12: 로컬·먹거리 | E12: 야경
A13: 통영·남해 섬 로맨스 | B13: 이순신공원 | C13: 힐링·생태 | D13: 해양·자연
A14: 통영·남해 섬 로맨스 | B14: 남해 보리암 | C14: 역사·문화 | D14: 해양·자연
A15: 통영·남해 섬 로맨스 | B15: 미조항 | C15: 로컬·먹거리 | D15: 해양·자연
A16: 키즈 애니 어드벤처 | B16: 에버랜드 | C16: 테마파크·액티비티 | E16: 야경
A17: 키즈 애니 어드벤처 | B17: 한국민속촌 | C17: 역사·문화 | D17: 테마파크·액티비티
A18: 키즈 애니 어드벤처 | B18: 레고랜드 | C18: 테마파크·액티비티
A19: 키즈 애니 어드벤처 | B19: 국립과천과학관 | C19: 테마파크·액티비티
A20: 키즈 애니 어드벤처 | B20: 헤이리 예술마을 | C20: 힐링·생태 | D20: 테마파크·액티비티
A21: 키즈 애니 어드벤처 | B21: 파주 퍼스트가든 | C21: 테마파크·액티비티 | D21: 힐링·생태 | E21: 야경
A22: 키즈 애니 어드벤처 | B22: 남이섬 | C22: 힐링·생태 | D22: 테마파크·액티비티
A23: 키즈 애니 어드벤처 | B23: 춘천 애니메이션박물관 | C23: 테마파크·액티비티 | D23: 역사·문화
A24: 키즈 애니 어드벤처 | B24: 춘천 닭갈비골목 | C24: 로컬·먹거리
A25: 키즈 애니 어드벤처 | B25: 국립수목원 | C25: 힐링·생태
A26: 대구·안동 먹방 예능 로드 | B26: 서문시장 야시장 | C26: 로컬·먹거리 | E26: 야경
A27: 대구·안동 먹방 예능 로드 | B27: 안지랑 곱창골목 | C27: 로컬·먹거리 | E27: 야경
A28: 대구·안동 먹방 예능 로드 | B28: 김광석 다시그리기길 | C28: 역사·문화 | D28: 힐링·생태
A29: 대구·안동 먹방 예능 로드 | B29: 안동 찜닭골목 | C29: 로컬·먹거리
A30: 대구·안동 먹방 예능 로드 | B30: 안동구시장 | C30: 로컬·먹거리 | D30: 역사·문화
A31: 대구·안동 먹방 예능 로드 | B31: 하회마을 | C31: 역사·문화 | D31: 힐링·생태
A32: 대구·안동 먹방 예능 로드 | B32: 월영교 | C32: 힐링·생태 | E32: 야경
A33: 대구·안동 먹방 예능 로드 | B33: 동성로 | C33: 로컬·먹거리 | D33: 테마파크·액티비티 | E33: 야경
A34: 대구·안동 먹방 예능 로드 | B34: 83타워 | C34: 테마파크·액티비티 | E34: 야경
A35: 대구·안동 먹방 예능 로드 | B35: 헛제사밥 까치구멍집 | C35: 로컬·먹거리 | D35: 역사·문화
